**Vamos falar sobre tratamento de erros em JavaScript usando `try`, `catch`, e `throw`!**

**Imagine que você está pilotando um carro em uma estrada cheia de buracos.** Em vez de esperar que o carro quebre quando encontrar um buraco, você pode usar o sistema de suspensão para suavizar o impacto e continuar dirigindo com segurança. Da mesma forma, em JavaScript, o tratamento de erros ajuda a lidar com situações inesperadas no código, permitindo que seu programa continue funcionando sem travar.

## Tratamento de Erro com `try`, `catch`, e `throw`

### 1. **Bloco `try`**

- **O que faz:** Executa um bloco de código que pode gerar um erro.
- **Exemplo:**

```javascript
try {
  // Código que pode gerar um erro
  let resultado = 10 / 0; // Isso gera Infinity, mas não é um erro
  console.log(resultado);
} catch (erro) {
  // Código para tratar o erro
  console.log("Ocorreu um erro:", erro);
}
```

### 2. **Bloco `catch`**

- **O que faz:** Captura e trata o erro que ocorreu no bloco `try`.
- **Exemplo:**

```javascript
try {
  // Código que pode gerar um erro
  let resultado = x + 1; // x não está definido
} catch (erro) {
  // Tratar o erro
  console.log("Erro capturado:", erro.message);
}
```

Aqui, o erro é capturado e sua mensagem é exibida.

### 3. **Bloco `finally`**

- **O que faz:** Executa um bloco de código após o `try` e `catch`, independentemente de um erro ter ocorrido ou não.
- **Exemplo:**

```javascript
try {
  console.log("Tentando executar código...");
  throw new Error("Algo deu errado!"); // Gera um erro para demonstrar o uso de `finally`
} catch (erro) {
  console.log("Erro capturado:", erro.message);
} finally {
  console.log("Código no bloco finally é sempre executado.");
}
```

Aqui, a mensagem do bloco `finally` será exibida independentemente do erro.

### 4. **Lançando Erros com `throw`**

- **O que faz:** Gera um erro manualmente. Isso pode ser usado para sinalizar que algo inesperado aconteceu.
- **Exemplo:**

```javascript
function verificaNumero(num) {
  if (num < 0) {
    throw new Error("Número não pode ser negativo.");
  }
  return num;
}

try {
  let resultado = verificaNumero(-5);
} catch (erro) {
  console.log("Erro capturado:", erro.message);
}
```

Aqui, `throw` gera um erro se `num` for negativo, que é então capturado e tratado no bloco `catch`.

## Resumo

- **`try`**: Tenta executar um bloco de código que pode gerar um erro.
- **`catch`**: Captura e trata o erro gerado no bloco `try`.
- **`finally`**: Executa um bloco de código após `try` e `catch`, independentemente de um erro ter ocorrido.
- **`throw`**: Gera um erro manualmente para sinalizar condições de erro.

## Quer saber mais?

Gostaria de explorar como tratar erros assíncronos com `async/await` e `try/catch`, ou tem outra pergunta sobre JavaScript?